[2022-02-12 13:32:43,390] {taskinstance.py:1032} INFO - Dependencies all met for <TaskInstance: test_dag.wget scheduled__2021-02-02T06:00:00+00:00 [queued]>
[2022-02-12 13:32:43,401] {taskinstance.py:1032} INFO - Dependencies all met for <TaskInstance: test_dag.wget scheduled__2021-02-02T06:00:00+00:00 [queued]>
[2022-02-12 13:32:43,401] {taskinstance.py:1238} INFO - 
--------------------------------------------------------------------------------
[2022-02-12 13:32:43,401] {taskinstance.py:1239} INFO - Starting attempt 2 of 2
[2022-02-12 13:32:43,402] {taskinstance.py:1240} INFO - 
--------------------------------------------------------------------------------
[2022-02-12 13:32:43,417] {taskinstance.py:1259} INFO - Executing <Task(BashOperator): wget> on 2021-02-02 06:00:00+00:00
[2022-02-12 13:32:43,422] {standard_task_runner.py:52} INFO - Started process 5729 to run task
[2022-02-12 13:32:43,427] {standard_task_runner.py:76} INFO - Running: ['***', 'tasks', 'run', 'test_dag', 'wget', 'scheduled__2021-02-02T06:00:00+00:00', '--job-id', '135', '--raw', '--subdir', 'DAGS_FOLDER/test_dag.py', '--cfg-path', '/tmp/tmpcuvb6_2l', '--error-file', '/tmp/tmpyv5ay7v6']
[2022-02-12 13:32:43,428] {standard_task_runner.py:77} INFO - Job 135: Subtask wget
[2022-02-12 13:32:43,495] {logging_mixin.py:109} INFO - Running <TaskInstance: test_dag.wget scheduled__2021-02-02T06:00:00+00:00 [running]> on host 8fc49de8f9da
[2022-02-12 13:32:43,575] {taskinstance.py:1426} INFO - Exporting the following env vars:
AIRFLOW_CTX_DAG_OWNER=***
AIRFLOW_CTX_DAG_ID=test_dag
AIRFLOW_CTX_TASK_ID=wget
AIRFLOW_CTX_EXECUTION_DATE=2021-02-02T06:00:00+00:00
AIRFLOW_CTX_DAG_RUN_ID=scheduled__2021-02-02T06:00:00+00:00
[2022-02-12 13:32:43,576] {subprocess.py:62} INFO - Tmp dir root location: 
 /tmp
[2022-02-12 13:32:43,577] {subprocess.py:74} INFO - Running command: ['bash', '-c', 'wget https://s3.amazonaws.com/nyc-tlc/trip+data/yellow_tripdate_2021-01.csv -O ./storage//output.csv']
[2022-02-12 13:32:43,587] {subprocess.py:85} INFO - Output:
[2022-02-12 13:32:43,589] {subprocess.py:89} INFO - bash: wget: command not found
[2022-02-12 13:32:43,590] {subprocess.py:93} INFO - Command exited with return code 127
[2022-02-12 13:32:43,610] {taskinstance.py:1700} ERROR - Task failed with exception
Traceback (most recent call last):
  File "/home/airflow/.local/lib/python3.7/site-packages/airflow/models/taskinstance.py", line 1329, in _run_raw_task
    self._execute_task_with_callbacks(context)
  File "/home/airflow/.local/lib/python3.7/site-packages/airflow/models/taskinstance.py", line 1455, in _execute_task_with_callbacks
    result = self._execute_task(context, self.task)
  File "/home/airflow/.local/lib/python3.7/site-packages/airflow/models/taskinstance.py", line 1511, in _execute_task
    result = execute_callable(context=context)
  File "/home/airflow/.local/lib/python3.7/site-packages/airflow/operators/bash.py", line 188, in execute
    f'Bash command failed. The command returned a non-zero exit code {result.exit_code}.'
airflow.exceptions.AirflowException: Bash command failed. The command returned a non-zero exit code 127.
[2022-02-12 13:32:43,621] {taskinstance.py:1277} INFO - Marking task as FAILED. dag_id=test_dag, task_id=wget, execution_date=20210202T060000, start_date=20220212T133243, end_date=20220212T133243
[2022-02-12 13:32:43,642] {standard_task_runner.py:92} ERROR - Failed to execute job 135 for task wget
Traceback (most recent call last):
  File "/home/airflow/.local/lib/python3.7/site-packages/airflow/task/task_runner/standard_task_runner.py", line 85, in _start_by_fork
    args.func(args, dag=self.dag)
  File "/home/airflow/.local/lib/python3.7/site-packages/airflow/cli/cli_parser.py", line 48, in command
    return func(*args, **kwargs)
  File "/home/airflow/.local/lib/python3.7/site-packages/airflow/utils/cli.py", line 92, in wrapper
    return f(*args, **kwargs)
  File "/home/airflow/.local/lib/python3.7/site-packages/airflow/cli/commands/task_command.py", line 298, in task_run
    _run_task_by_selected_method(args, dag, ti)
  File "/home/airflow/.local/lib/python3.7/site-packages/airflow/cli/commands/task_command.py", line 107, in _run_task_by_selected_method
    _run_raw_task(args, ti)
  File "/home/airflow/.local/lib/python3.7/site-packages/airflow/cli/commands/task_command.py", line 184, in _run_raw_task
    error_file=args.error_file,
  File "/home/airflow/.local/lib/python3.7/site-packages/airflow/utils/session.py", line 70, in wrapper
    return func(*args, session=session, **kwargs)
  File "/home/airflow/.local/lib/python3.7/site-packages/airflow/models/taskinstance.py", line 1329, in _run_raw_task
    self._execute_task_with_callbacks(context)
  File "/home/airflow/.local/lib/python3.7/site-packages/airflow/models/taskinstance.py", line 1455, in _execute_task_with_callbacks
    result = self._execute_task(context, self.task)
  File "/home/airflow/.local/lib/python3.7/site-packages/airflow/models/taskinstance.py", line 1511, in _execute_task
    result = execute_callable(context=context)
  File "/home/airflow/.local/lib/python3.7/site-packages/airflow/operators/bash.py", line 188, in execute
    f'Bash command failed. The command returned a non-zero exit code {result.exit_code}.'
airflow.exceptions.AirflowException: Bash command failed. The command returned a non-zero exit code 127.
[2022-02-12 13:32:43,676] {local_task_job.py:154} INFO - Task exited with return code 1
[2022-02-12 13:32:43,738] {local_task_job.py:264} INFO - 0 downstream tasks scheduled from follow-on schedule check
