[2022-02-12 20:19:22,331] {taskinstance.py:1032} INFO - Dependencies all met for <TaskInstance: test_dag.ingest scheduled__2021-01-02T06:00:00+00:00 [queued]>
[2022-02-12 20:19:22,343] {taskinstance.py:1032} INFO - Dependencies all met for <TaskInstance: test_dag.ingest scheduled__2021-01-02T06:00:00+00:00 [queued]>
[2022-02-12 20:19:22,343] {taskinstance.py:1238} INFO - 
--------------------------------------------------------------------------------
[2022-02-12 20:19:22,343] {taskinstance.py:1239} INFO - Starting attempt 6 of 6
[2022-02-12 20:19:22,343] {taskinstance.py:1240} INFO - 
--------------------------------------------------------------------------------
[2022-02-12 20:19:22,357] {taskinstance.py:1259} INFO - Executing <Task(PythonOperator): ingest> on 2021-01-02 06:00:00+00:00
[2022-02-12 20:19:22,362] {standard_task_runner.py:52} INFO - Started process 22453 to run task
[2022-02-12 20:19:22,367] {standard_task_runner.py:76} INFO - Running: ['***', 'tasks', 'run', 'test_dag', 'ingest', 'scheduled__2021-01-02T06:00:00+00:00', '--job-id', '167', '--raw', '--subdir', 'DAGS_FOLDER/test_dag.py', '--cfg-path', '/tmp/tmp65b4r_cq', '--error-file', '/tmp/tmpxi52ul23']
[2022-02-12 20:19:22,369] {standard_task_runner.py:77} INFO - Job 167: Subtask ingest
[2022-02-12 20:19:22,434] {logging_mixin.py:109} INFO - Running <TaskInstance: test_dag.ingest scheduled__2021-01-02T06:00:00+00:00 [running]> on host 316131e7aea8
[2022-02-12 20:19:22,491] {logging_mixin.py:109} WARNING - /home/***/.local/lib/python3.7/site-packages/***/utils/context.py:152 AirflowContextDeprecationWarning: Accessing 'execution_date' from the template is deprecated and will be removed in a future version. Please use 'data_interval_start' or 'logical_date' instead.
[2022-02-12 20:19:22,514] {taskinstance.py:1426} INFO - Exporting the following env vars:
AIRFLOW_CTX_DAG_OWNER=***
AIRFLOW_CTX_DAG_ID=test_dag
AIRFLOW_CTX_TASK_ID=ingest
AIRFLOW_CTX_EXECUTION_DATE=2021-01-02T06:00:00+00:00
AIRFLOW_CTX_DAG_RUN_ID=scheduled__2021-01-02T06:00:00+00:00
[2022-02-12 20:19:22,515] {logging_mixin.py:109} INFO - ??? /opt/***/yellow_tripdata_2021-01.csv 2021-01-02T06:00:00+00:00
[2022-02-12 20:19:22,515] {taskinstance.py:1700} ERROR - Task failed with exception
Traceback (most recent call last):
  File "/home/airflow/.local/lib/python3.7/site-packages/airflow/models/taskinstance.py", line 1329, in _run_raw_task
    self._execute_task_with_callbacks(context)
  File "/home/airflow/.local/lib/python3.7/site-packages/airflow/models/taskinstance.py", line 1455, in _execute_task_with_callbacks
    result = self._execute_task(context, self.task)
  File "/home/airflow/.local/lib/python3.7/site-packages/airflow/models/taskinstance.py", line 1511, in _execute_task
    result = execute_callable(context=context)
  File "/home/airflow/.local/lib/python3.7/site-packages/airflow/operators/python.py", line 174, in execute
    return_value = self.execute_callable()
  File "/home/airflow/.local/lib/python3.7/site-packages/airflow/operators/python.py", line 185, in execute_callable
    return self.python_callable(*self.op_args, **self.op_kwargs)
  File "/opt/airflow/dags/ingest_script.py", line 12, in ingest_callable
    engine = create_engine(f'postgresql://{user}:{password}@{host}:{port}/{db}')
  File "/home/airflow/.local/lib/python3.7/site-packages/sqlalchemy/engine/__init__.py", line 525, in create_engine
    return strategy.create(*args, **kwargs)
  File "/home/airflow/.local/lib/python3.7/site-packages/sqlalchemy/engine/strategies.py", line 54, in create
    u = url.make_url(name_or_url)
  File "/home/airflow/.local/lib/python3.7/site-packages/sqlalchemy/engine/url.py", line 229, in make_url
    return _parse_rfc1738_args(name_or_url)
  File "/home/airflow/.local/lib/python3.7/site-packages/sqlalchemy/engine/url.py", line 288, in _parse_rfc1738_args
    return URL(name, **components)
  File "/home/airflow/.local/lib/python3.7/site-packages/sqlalchemy/engine/url.py", line 71, in __init__
    self.port = int(port)
ValueError: invalid literal for int() with base 10: 'None'
[2022-02-12 20:19:22,533] {taskinstance.py:1277} INFO - Marking task as FAILED. dag_id=test_dag, task_id=ingest, execution_date=20210102T060000, start_date=20220212T201922, end_date=20220212T201922
[2022-02-12 20:19:22,552] {standard_task_runner.py:92} ERROR - Failed to execute job 167 for task ingest
Traceback (most recent call last):
  File "/home/airflow/.local/lib/python3.7/site-packages/airflow/task/task_runner/standard_task_runner.py", line 85, in _start_by_fork
    args.func(args, dag=self.dag)
  File "/home/airflow/.local/lib/python3.7/site-packages/airflow/cli/cli_parser.py", line 48, in command
    return func(*args, **kwargs)
  File "/home/airflow/.local/lib/python3.7/site-packages/airflow/utils/cli.py", line 92, in wrapper
    return f(*args, **kwargs)
  File "/home/airflow/.local/lib/python3.7/site-packages/airflow/cli/commands/task_command.py", line 298, in task_run
    _run_task_by_selected_method(args, dag, ti)
  File "/home/airflow/.local/lib/python3.7/site-packages/airflow/cli/commands/task_command.py", line 107, in _run_task_by_selected_method
    _run_raw_task(args, ti)
  File "/home/airflow/.local/lib/python3.7/site-packages/airflow/cli/commands/task_command.py", line 184, in _run_raw_task
    error_file=args.error_file,
  File "/home/airflow/.local/lib/python3.7/site-packages/airflow/utils/session.py", line 70, in wrapper
    return func(*args, session=session, **kwargs)
  File "/home/airflow/.local/lib/python3.7/site-packages/airflow/models/taskinstance.py", line 1329, in _run_raw_task
    self._execute_task_with_callbacks(context)
  File "/home/airflow/.local/lib/python3.7/site-packages/airflow/models/taskinstance.py", line 1455, in _execute_task_with_callbacks
    result = self._execute_task(context, self.task)
  File "/home/airflow/.local/lib/python3.7/site-packages/airflow/models/taskinstance.py", line 1511, in _execute_task
    result = execute_callable(context=context)
  File "/home/airflow/.local/lib/python3.7/site-packages/airflow/operators/python.py", line 174, in execute
    return_value = self.execute_callable()
  File "/home/airflow/.local/lib/python3.7/site-packages/airflow/operators/python.py", line 185, in execute_callable
    return self.python_callable(*self.op_args, **self.op_kwargs)
  File "/opt/airflow/dags/ingest_script.py", line 12, in ingest_callable
    engine = create_engine(f'postgresql://{user}:{password}@{host}:{port}/{db}')
  File "/home/airflow/.local/lib/python3.7/site-packages/sqlalchemy/engine/__init__.py", line 525, in create_engine
    return strategy.create(*args, **kwargs)
  File "/home/airflow/.local/lib/python3.7/site-packages/sqlalchemy/engine/strategies.py", line 54, in create
    u = url.make_url(name_or_url)
  File "/home/airflow/.local/lib/python3.7/site-packages/sqlalchemy/engine/url.py", line 229, in make_url
    return _parse_rfc1738_args(name_or_url)
  File "/home/airflow/.local/lib/python3.7/site-packages/sqlalchemy/engine/url.py", line 288, in _parse_rfc1738_args
    return URL(name, **components)
  File "/home/airflow/.local/lib/python3.7/site-packages/sqlalchemy/engine/url.py", line 71, in __init__
    self.port = int(port)
ValueError: invalid literal for int() with base 10: 'None'
[2022-02-12 20:19:22,577] {local_task_job.py:154} INFO - Task exited with return code 1
[2022-02-12 20:19:22,622] {local_task_job.py:264} INFO - 0 downstream tasks scheduled from follow-on schedule check
